<robot name="opus">
  <link name="base">
    <inertial>
      <origin rpy="0 0 0" xyz="0 0 0" />
      <mass value="0.001" />
      <inertia ixx="0.0001" ixy="0" ixz="0" iyy="0.0001" iyz="0" izz="0.0001" />
    </inertial>
  </link>
  <joint name="floating_base" type="fixed">
    <origin rpy="0 0 0" xyz="0 0 0" />
    <parent link="base" />
    <child link="Torso" />
  </joint>
  <link name="Torso">
    <visual>
      <origin xyz="0 0 0" rpy="0 0 0" />
      <geometry>
        <mesh filename="meshes/Torso.stl" />
      </geometry>
      <material name="Torso_material">
        <color rgba="0.97254902 0.52941176 0.0039215686 1" />
      </material>
    </visual>
    <collision>
      <origin xyz="0 0 0" rpy="0 0 0" />
      <geometry>
        <mesh filename="meshes/Torso.stl" />
      </geometry>
    </collision>
    <inertial>
      <mass value="1.5697539312" />
      <inertia ixx="0.0056060930975062925" iyy="0.0073310764831877725" izz="0.002555258648683461" ixy="5.455941982626269e-06" ixz="-8.678303814394845e-05" iyz="0.00034633637897867406" />
      <origin xyz="0.0006379977765356807 0.0037125891477163145 -0.0018039549717621631" rpy="0 0 0" />
    </inertial>
  </link>
  <joint name="right_shoulder_pitch" type="fixed">
    <origin xyz="-0.07813646375169968 -0.0003355559182753147 0.04305328991827533" rpy="1.5707963 2.220446049250313e-16 1.5707963" />
    <parent link="Torso" />
    <child link="shoulder_yaw_right" />
    <limit effort="1" velocity="20" lower="-1.5707963" upper="1.5707963" />
    <axis xyz="0 0 1" />
  </joint>
  <link name="shoulder_yaw_right">
    <visual>
      <origin xyz="0 0 0" rpy="0 0 0" />
      <geometry>
        <mesh filename="meshes/shoulder_yaw_right.stl" />
      </geometry>
      <material name="shoulder_yaw_right_material">
        <color rgba="0.97254902 0.52941176 0.0039215686 1" />
      </material>
    </visual>
    <collision>
      <origin xyz="0 0 0" rpy="0 0 0" />
      <geometry>
        <mesh filename="meshes/shoulder_yaw_right.stl" />
      </geometry>
    </collision>
    <inertial>
      <mass value="0.040362728" />
      <inertia ixx="1.0226821e-05" iyy="2.2303144e-05" izz="2.1988958e-05" ixy="0" ixz="0" iyz="-1.8359103e-06" />
      <origin xyz="-0.00037600968 -0.0036566476 -0.017432914" rpy="0 0 0" />
    </inertial>
  </link>
  <joint name="left_shoulder_pitch" type="fixed">
    <origin xyz="0.0781635406483003 -0.0003355560817246521 0.04305329008172466" rpy="-1.5707963071795865 0.0 1.5707963000000003" />
    <parent link="Torso" />
    <child link="shoulder_yaw_left" />
    <limit effort="1" velocity="20" lower="-1.5707963" upper="1.5707963" />
    <axis xyz="0 0 1" />
  </joint>
  <link name="shoulder_yaw_left">
    <visual>
      <origin xyz="0 0 0" rpy="0 0 0" />
      <geometry>
        <mesh filename="meshes/shoulder_yaw_left.stl" />
      </geometry>
      <material name="shoulder_yaw_left_material">
        <color rgba="0.97254902 0.52941176 0.0039215686 1" />
      </material>
    </visual>
    <collision>
      <origin xyz="0 0 0" rpy="0 0 0" />
      <geometry>
        <mesh filename="meshes/shoulder_yaw_left.stl" />
      </geometry>
    </collision>
    <inertial>
      <mass value="0.040363129" />
      <inertia ixx="1.0227007e-05" iyy="2.2303258e-05" izz="2.1989069e-05" ixy="0" ixz="0" iyz="1.8360421e-06" />
      <origin xyz="-0.00037590896 0.0036565205 -0.017432695" rpy="0 0 0" />
    </inertial>
  </link>
  <joint name="right_shoulder_yaw" type="fixed">
    <origin xyz="-0.018825 -0.01629921 -0.03" rpy="3.1415927 -1.5707963 0" />
    <parent link="shoulder_yaw_right" />
    <child link="right_shoulder_yaw_motor" />
    <limit effort="1" velocity="20" lower="-1.5707963" upper="1.5707963" />
    <axis xyz="0 0 -1" />
  </joint>
  <link name="right_shoulder_yaw_motor">
    <visual>
      <origin xyz="0 0 0" rpy="0 0 0" />
      <geometry>
        <mesh filename="meshes/right_shoulder_yaw_motor.stl" />
      </geometry>
      <material name="right_shoulder_yaw_motor_material">
        <color rgba="0.4 0.4 0.4 1" />
      </material>
    </visual>
    <collision>
      <origin xyz="0 0 0" rpy="0 0 0" />
      <geometry>
        <mesh filename="meshes/right_shoulder_yaw_motor.stl" />
      </geometry>
    </collision>
    <inertial>
      <mass value="0.17145988099999998" />
      <inertia ixx="0.00013262325307405754" iyy="6.0724117002077606e-05" izz="0.00013875614802904093" ixy="4.288149187392555e-05" ixz="1.8301480028463223e-07" iyz="-3.923791483229383e-07" />
      <origin xyz="-0.014954779548987598 0.03207058001285851 0.01810151127113155" rpy="0 0 0" />
    </inertial>
  </link>
  <joint name="right_hip_pitch" type="revolute">
    <origin xyz="-0.04563646320240432 -0.00033555485567163604 -0.09694671547403086" rpy="-1.570796353589792 -4.6410206566704915e-08 1.5707963000000003" />
    <parent link="Torso" />
    <child link="hip_yaw_right" />
    <limit effort="1" velocity="20" lower="-1.5707963" upper="1.5707963" />
    <axis xyz="0 0 -1" />
  </joint>
  <link name="hip_yaw_right">
    <visual>
      <origin xyz="0 0 0" rpy="0 0 0" />
      <geometry>
        <mesh filename="meshes/hip_yaw_right.stl" />
      </geometry>
      <material name="hip_yaw_right_material">
        <color rgba="0.97254902 0.52941176 0.0039215686 1" />
      </material>
    </visual>
    <collision>
      <origin xyz="0 0 0" rpy="0 0 0" />
      <geometry>
        <mesh filename="meshes/hip_yaw_right.stl" />
      </geometry>
    </collision>
    <inertial>
      <mass value="0.10319577099999999" />
      <inertia ixx="4.318575205232385e-05" iyy="3.6230883570948907e-05" izz="3.840805007327843e-05" ixy="-2.9128945888629886e-08" ixz="-6.96211329136451e-08" iyz="3.2487836840400852e-06" />
      <origin xyz="-0.007775213144040673 -0.010188892005385952 0.015272495649744542" rpy="0 0 0" />
    </inertial>
  </link>
  <joint name="left_hip_pitch" type="revolute">
    <origin xyz="0.04566353964830031 -0.0003355550191209561 -0.09694671547403086" rpy="1.5707963535897942 -4.6410206566704915e-08 1.5707963000000003" />
    <parent link="Torso" />
    <child link="hip_yaw_left" />
    <limit effort="1" velocity="20" lower="-1.5707963" upper="1.5707963" />
    <axis xyz="0 0 -1" />
  </joint>
  <link name="hip_yaw_left">
    <visual>
      <origin xyz="0 0 0" rpy="0 0 0" />
      <geometry>
        <mesh filename="meshes/hip_yaw_left.stl" />
      </geometry>
      <material name="hip_yaw_left_material">
        <color rgba="0.97254902 0.52941176 0.0039215686 1" />
      </material>
    </visual>
    <collision>
      <origin xyz="0 0 0" rpy="0 0 0" />
      <geometry>
        <mesh filename="meshes/hip_yaw_left.stl" />
      </geometry>
    </collision>
    <inertial>
      <mass value="0.103201904" />
      <inertia ixx="4.31868121602293e-05" iyy="3.623346153388101e-05" izz="3.8409711336322e-05" ixy="2.9558133603560806e-08" ixz="-7.066797363081703e-08" iyz="-3.2490435867892277e-06" />
      <origin xyz="-0.007776157110492239 0.010188687432665504 0.015271760814946028" rpy="0 0 0" />
    </inertial>
  </link>
  <joint name="left_shoulder_yaw" type="fixed">
    <origin xyz="-0.018825 0.01629921 -0.03" rpy="3.1415927 1.5707963 0" />
    <parent link="shoulder_yaw_left" />
    <child link="left_shoulder_yaw_motor" />
    <limit effort="1" velocity="20" lower="-1.5707963" upper="1.5707963" />
    <axis xyz="0 0 1" />
  </joint>
  <link name="left_shoulder_yaw_motor">
    <visual>
      <origin xyz="0 0 0" rpy="0 0 0" />
      <geometry>
        <mesh filename="meshes/left_shoulder_yaw_motor.stl" />
      </geometry>
      <material name="left_shoulder_yaw_motor_material">
        <color rgba="0.4 0.4 0.4 1" />
      </material>
    </visual>
    <collision>
      <origin xyz="0 0 0" rpy="0 0 0" />
      <geometry>
        <mesh filename="meshes/left_shoulder_yaw_motor.stl" />
      </geometry>
    </collision>
    <inertial>
      <mass value="0.171459652" />
      <inertia ixx="0.00013262990226591847" iyy="6.071731649741009e-05" izz="0.0001387561460545798" ixy="4.2373954399027645e-05" ixz="1.8300960471168456e-07" iyz="-3.9237987690711426e-07" />
      <origin xyz="0.01495475586438801 -0.03207058301892832 -0.018101540546377845" rpy="0 0 0" />
    </inertial>
  </link>
  <joint name="right_hip_yaw" type="revolute">
    <origin xyz="-0.02550000162875169 0.0025000011415515153 0.019359999918275368" rpy="9.282041333256968e-08 1.5707963000000005 0.0" />
    <parent link="hip_yaw_right" />
    <child link="hip_roll_right" />
    <limit effort="1" velocity="20" lower="-0.087266463" upper="1.5707963" />
    <axis xyz="0 0 1" />
  </joint>
  <link name="hip_roll_right">
    <visual>
      <origin xyz="0 0 0" rpy="0 0 0" />
      <geometry>
        <mesh filename="meshes/hip_roll_right.stl" />
      </geometry>
      <material name="hip_roll_right_material">
        <color rgba="0.97254902 0.52941176 0.0039215686 1" />
      </material>
    </visual>
    <collision>
      <origin xyz="0 0 0" rpy="0 0 0" />
      <geometry>
        <mesh filename="meshes/hip_roll_right.stl" />
      </geometry>
    </collision>
    <inertial>
      <mass value="0.111293388" />
      <inertia ixx="6.57187282381467e-05" iyy="3.611810901444388e-05" izz="4.5395675003437e-05" ixy="8.212582995854536e-08" ixz="-2.2471146072130633e-08" iyz="-3.4518887360620174e-06" />
      <origin xyz="5.2211227247596255e-05 0.04271834544407224 0.027962543113983985" rpy="0 0 0" />
    </inertial>
  </link>
  <joint name="left_hip_yaw" type="revolute">
    <origin xyz="-0.02550000297464769 -0.0025000010000000017 0.01936000008172467" rpy="-3.1415926071795863 -1.5707963 0.0" />
    <parent link="hip_yaw_left" />
    <child link="hip_roll_left" />
    <limit effort="1" velocity="20" lower="-1.5707963" upper="0.087266463" />
    <axis xyz="0 0 1" />
  </joint>
  <link name="hip_roll_left">
    <visual>
      <origin xyz="0 0 0" rpy="0 0 0" />
      <geometry>
        <mesh filename="meshes/hip_roll_left.stl" />
      </geometry>
      <material name="hip_roll_left_material">
        <color rgba="0.97254902 0.52941176 0.0039215686 1" />
      </material>
    </visual>
    <collision>
      <origin xyz="0 0 0" rpy="0 0 0" />
      <geometry>
        <mesh filename="meshes/hip_roll_left.stl" />
      </geometry>
    </collision>
    <inertial>
      <mass value="0.111293526" />
      <inertia ixx="6.571885628721675e-05" iyy="3.6118218228694584e-05" izz="4.539570186252418e-05" ixy="-8.212631041317914e-08" ixz="2.2471679414859696e-08" iyz="-3.4519619781216844e-06" />
      <origin xyz="-5.2212826152564546e-05 0.04271835909112089 0.027962565619545642" rpy="0 0 0" />
    </inertial>
  </link>
  <joint name="right_elbow_yaw" type="fixed">
    <origin xyz="-0.03000311610855749 0.06434189253104221 0.00025000101875458525" rpy="8.847213864293657e-08 -1.9613800805728943e-08 0.4363323099999996" />
    <parent link="right_shoulder_yaw_motor" />
    <child link="Left_Hand" />
    <limit effort="1" velocity="20" lower="-1.2217305" upper="1.2217305" />
    <axis xyz="0 0 1" />
  </joint>
  <link name="Left_Hand">
    <visual>
      <origin xyz="0 0 0" rpy="0 0 0" />
      <geometry>
        <mesh filename="meshes/Left_Hand.stl" />
      </geometry>
      <material name="Left_Hand_material">
        <color rgba="0.97254902 0.52941176 0.0039215686 1" />
      </material>
    </visual>
    <collision>
      <origin xyz="0 0 0" rpy="0 0 0" />
      <geometry>
        <mesh filename="meshes/Left_Hand.stl" />
      </geometry>
    </collision>
    <inertial>
      <mass value="0.075184887" />
      <inertia ixx="5.6585944e-05" iyy="1.4864722e-05" izz="4.710315e-05" ixy="-2.4063655e-06" ixz="0" iyz="0" />
      <origin xyz="0.0011184952 0.046132358 0.018254412" rpy="0 0 0" />
    </inertial>
  </link>
  <joint name="left_elbow_yaw" type="fixed">
    <origin xyz="0.03000311710160605 -0.06434189183411612 -0.0002500013458960012" rpy="-3.141592607179586 -2.220446049250313e-16 0.43633231000000006" />
    <parent link="left_shoulder_yaw_motor" />
    <child link="hand_right" />
    <limit effort="1" velocity="20" lower="-1.2217305" upper="1.2217305" />
    <axis xyz="0 0 1" />
  </joint>
  <link name="hand_right">
    <visual>
      <origin xyz="0 0 0" rpy="0 0 0" />
      <geometry>
        <mesh filename="meshes/hand_right.stl" />
      </geometry>
      <material name="hand_right_material">
        <color rgba="0.97254902 0.52941176 0.0039215686 1" />
      </material>
    </visual>
    <collision>
      <origin xyz="0 0 0" rpy="0 0 0" />
      <geometry>
        <mesh filename="meshes/hand_right.stl" />
      </geometry>
    </collision>
    <inertial>
      <mass value="0.075183656" />
      <inertia ixx="5.6585045e-05" iyy="1.4864063e-05" izz="4.7102936e-05" ixy="2.4062028e-06" ixz="0" iyz="0" />
      <origin xyz="-0.0011185716 0.046132566 0.018254616" rpy="0 0 0" />
    </inertial>
  </link>
  <joint name="right_hip_roll" type="revolute">
    <origin xyz="0.0 0.06776001387753285 0.015000000939161373" rpy="1.5707963999999996 0.0 0.0" />
    <parent link="hip_roll_right" />
    <child link="knee_pitch_right" />
    <limit effort="1" velocity="20" lower="-0.78539816" upper="0.78539816" />
    <axis xyz="0 0 1" />
  </joint>
  <link name="knee_pitch_right">
    <visual>
      <origin xyz="0 0 0" rpy="0 0 0" />
      <geometry>
        <mesh filename="meshes/knee_pitch_right.stl" />
      </geometry>
      <material name="knee_pitch_right_material">
        <color rgba="0.97254902 0.52941176 0.0039215686 1" />
      </material>
    </visual>
    <collision>
      <origin xyz="0 0 0" rpy="0 0 0" />
      <geometry>
        <mesh filename="meshes/knee_pitch_right.stl" />
      </geometry>
    </collision>
    <inertial>
      <mass value="0.11061241299999999" />
      <inertia ixx="6.256455107906355e-05" iyy="6.848300154382249e-05" izz="2.7272974458875817e-05" ixy="-1.7202857813824897e-07" ixz="6.756595730316172e-07" iyz="6.994109024317401e-06" />
      <origin xyz="0.0007189519537218518 -0.0023746643916922137 -0.021913106490424647" rpy="0 0 0" />
    </inertial>
  </link>
  <joint name="left_hip_roll" type="revolute">
    <origin xyz="0.0 0.06776001212246713 0.014999999060838654" rpy="1.5707963 0.0 0.0" />
    <parent link="hip_roll_left" />
    <child link="knee_pitch_right_2" />
    <limit effort="1" velocity="20" lower="-0.78539816" upper="0.78539816" />
    <axis xyz="0 0 1" />
  </joint>
  <link name="knee_pitch_right_2">
    <visual>
      <origin xyz="0 0 0" rpy="0 0 0" />
      <geometry>
        <mesh filename="meshes/knee_pitch_right_2.stl" />
      </geometry>
      <material name="knee_pitch_right_material_2">
        <color rgba="0.97254902 0.52941176 0.0039215686 1" />
      </material>
    </visual>
    <collision>
      <origin xyz="0 0 0" rpy="0 0 0" />
      <geometry>
        <mesh filename="meshes/knee_pitch_right_2.stl" />
      </geometry>
    </collision>
    <inertial>
      <mass value="0.11061241299999999" />
      <inertia ixx="6.811358369755594e-05" iyy="7.403582703586009e-05" izz="2.7276767279426143e-05" ixy="1.8563071717604188e-07" ixz="-8.248656959451613e-07" iyz="7.656982124567568e-06" />
      <origin xyz="-0.0006438206184322414 -0.0023746644421732206 -0.024438821233669406" rpy="0 0 0" />
    </inertial>
  </link>
  <joint name="right_knee_pitch" type="revolute">
    <origin xyz="0.01882501239711481 -9.39161338975314e-10 -0.04221000153916135" rpy="-1.5707963 0.0 1.5707963" />
    <parent link="knee_pitch_right" />
    <child link="ankle_pitch_right" />
    <limit effort="1" velocity="20" lower="-1.0471976" upper="1.0471976" />
    <axis xyz="0 0 1" />
  </joint>
  <link name="ankle_pitch_right">
    <visual>
      <origin xyz="0 0 0" rpy="0 0 0" />
      <geometry>
        <mesh filename="meshes/ankle_pitch_right.stl" />
      </geometry>
      <material name="ankle_pitch_right_material">
        <color rgba="0.97254902 0.52941176 0.0039215686 1" />
      </material>
    </visual>
    <collision>
      <origin xyz="0 0 0" rpy="0 0 0" />
      <geometry>
        <mesh filename="meshes/ankle_pitch_right.stl" />
      </geometry>
    </collision>
    <inertial>
      <mass value="0.109625116" />
      <inertia ixx="5.751366326764494e-05" iyy="2.786435696863557e-05" izz="4.601315056057759e-05" ixy="2.781681647488596e-09" ixz="-2.535829062531046e-11" iyz="1.4671593859070324e-07" />
      <origin xyz="-5.290268857115649e-07 0.04092239693101483 0.017864163896558594" rpy="0 0 0" />
    </inertial>
  </link>
  <joint name="left_knee_pitch" type="revolute">
    <origin xyz="-0.018775013847819433 9.3916133203642e-10 -0.04596000193916135" rpy="-1.5707963071795865 0.0 1.5707963000000003" />
    <parent link="knee_pitch_right_2" />
    <child link="ankle_pitch_left" />
    <limit effort="1" velocity="20" lower="-1.0471976" upper="1.0471976" />
    <axis xyz="0 0 -1" />
  </joint>
  <link name="ankle_pitch_left">
    <visual>
      <origin xyz="0 0 0" rpy="0 0 0" />
      <geometry>
        <mesh filename="meshes/ankle_pitch_left.stl" />
      </geometry>
      <material name="ankle_pitch_left_material">
        <color rgba="0.97254902 0.52941176 0.0039215686 1" />
      </material>
    </visual>
    <collision>
      <origin xyz="0 0 0" rpy="0 0 0" />
      <geometry>
        <mesh filename="meshes/ankle_pitch_left.stl" />
      </geometry>
    </collision>
    <inertial>
      <mass value="0.109625115" />
      <inertia ixx="5.332419486756842e-05" iyy="2.7987836076502866e-05" izz="4.170020090666129e-05" ixy="3.0260808403941346e-10" ixz="-3.119719583279756e-11" iyz="1.212609004459173e-06" />
      <origin xyz="2.1519678784208124e-06 0.03837394107872274 -0.01957899760073858" rpy="0 0 0" />
    </inertial>
  </link>
  <joint name="right_ankle_pitch" type="revolute">
    <origin xyz="0.0 0.060220001 -1.3000000000096268e-08" rpy="-3.1415926071795863 0.0 0.0" />
    <parent link="ankle_pitch_right" />
    <child link="foot_right" />
    <limit effort="1" velocity="20" lower="-1.0471976" upper="1.0471976" />
    <axis xyz="0 0 -1" />
  </joint>
  <link name="foot_right">
    <visual>
      <origin xyz="0 0 0" rpy="0 0 0" />
      <geometry>
        <mesh filename="meshes/foot_right.stl" />
      </geometry>
      <material name="foot_right_material">
        <color rgba="0.97254902 0.52941176 0.0039215686 1" />
      </material>
    </visual>
    <collision>
      <origin xyz="0 0 0" rpy="0 0 0" />
      <geometry>
        <mesh filename="meshes/foot_right.stl" />
      </geometry>
    </collision>
    <inertial>
      <mass value="0.040622158" />
      <inertia ixx="1.3644671e-05" iyy="3.7817973e-05" izz="2.8893973e-05" ixy="-1.0762297e-06" ixz="0" iyz="0" />
      <origin xyz="-0.0077822731 -0.016191375 -0.017831949" rpy="0 0 0" />
    </inertial>
  </link>
  <joint name="left_ankle_pitch" type="revolute">
    <origin xyz="1.3458959276929638e-09 0.05646999986991183 -0.0004500036541040392" rpy="-3.1415926071795863 2.220446049250313e-15 -9.282041313340983e-08" />
    <parent link="ankle_pitch_left" />
    <child link="foot_left" />
    <limit effort="1" velocity="20" lower="-1.0471976" upper="1.0471976" />
    <axis xyz="0 0 1" />
  </joint>
  <link name="foot_left">
    <visual>
      <origin xyz="0 0 0" rpy="0 0 0" />
      <geometry>
        <mesh filename="meshes/foot_left.stl" />
      </geometry>
      <material name="foot_left_material">
        <color rgba="0.97254902 0.52941176 0.0039215686 1" />
      </material>
    </visual>
    <collision>
      <origin xyz="0 0 0" rpy="0 0 0" />
      <geometry>
        <mesh filename="meshes/foot_left.stl" />
      </geometry>
    </collision>
    <inertial>
      <mass value="0.04062216" />
      <inertia ixx="1.3644672e-05" iyy="3.7817974e-05" izz="2.8893973e-05" ixy="-1.0762295e-06" ixz="0" iyz="0" />
      <origin xyz="-0.0077822737 -0.016191375 0.01783195" rpy="0 0 0" />
    </inertial>
  </link>
</robot>